---
title: "【1.2】raise文で特定の例外を発生させる"
date: 2023-08-17T22:24:22+09:00
tags: [""]
seq: [""]
draft: false
---

- `raise`で特定の例外を発生させることができる

```python
raise ValueError("Hello")

----------------------------------------
>>> raise ValueError("Hello")
Traceback (most recent call last):
  File "<stdin>", line 1, in <module>
ValueError: Hello
```

- `BaseException`あるいは、`Exception`を継承した例外クラスでなければならない
  - 例外を自作する場合は注意する

- 例外を再送出することもできる

```python
try:
    raise NameError('HiThere')
except NameError:
    print('An exception flew by!')
    raise

An exception flew by!
Traceback (most recent call last):
  File "<stdin>", line 2, in <module>
NameError: HiThere
```
- ある例外がほかの例外から連鎖していることを示す場合には、`from`を使う
  - `from None`でこれを無効化できる

```python
def func():
    raise ConnectionError

try:
    func()
except ConnectionError as exc:
    raise RuntimeError('Failed to open database') from exc

Traceback (most recent call last):
  File "<stdin>", line 2, in <module>
  File "<stdin>", line 2, in func
ConnectionError

The above exception was the direct cause of the following exception:

Traceback (most recent call last):
  File "<stdin>", line 4, in <module>
RuntimeError: Failed to open database
```