---
title: "【1.1】try~exceptで終了させたい時"
date: 2023-08-17T22:10:00+09:00
tags: [""]
seq: [""]
draft: false
---

- `try ... except ...`で終了させたい時は`sys.exit()`を使う

```python
import logging
import sys

try:
    1/0
except (ValueError,ZeroDivisionError):
    logging.warning("test")
    sys.exit(1)

print(1+1)

-------------------------------------------
WARNING:root:test
```

- 注意点として、`try`句の中では`exit`できない
  - `exit`は例外を発生させて終了するため
- そのため、関数呼び出しの時などは注意する

```python
# これは終了しない
def test():
    try:
        1/0
    except ZeroDivisionError:
        logging.warning("testの中")
        sys.exit(1)

try:
    test()
except (ValueError,ZeroDivisionError):
    logging.warning("test")
```

```python
# これは終了する
def test():
    try:
        1/0
    except ZeroDivisionError:
        logging.warning("testの中")

try:
    test()
except (ValueError,ZeroDivisionError):
    logging.warning("test")
    sys.exit(1)
```