---
title: "【11.21.1】tryとexceptによるエラー処理"
date: 2023-08-07T00:17:36+09:00
tags: [""]
seq: [""]
draft: false
---

- tryを使って例外が発生しそうな場所を囲み、exceptを使って例外処理を提供する


```python
>>> short_list = [1, 2, 3]
>>> position = 5
>>> try:
...     short_list[position]
... except:
...     print('Need a position between 0 and', len(short_list) - 1, ' but got', position)
...
Need a position between 0 and 2  but got 5
```

- 複数の例外が発生する可能性があるときには、それぞれのために別々の例外ハンドラを用意した方がいい
  - `except exceptiontype as name`のようにして、例外オブジェクトをname変数に格納できる

```python
>>> short_list = [1, 2, 3]
>>> while True:
...     value = input('Position [q to quit]? ')
...     if value == 'q':
...         break
...     try:
...         position = int(value)
...         print(short_list[position])
...     except IndexError as err:
...         print('Bad index', position)
...     except Exception as other:
...         print('Something else broke:', other)
...
Position [q to quit]? 1
2
Position [q to quit]? 2
3
Position [q to quit]? 3
Bad index 3
Position [q to quit]? 4
Bad index 4
Position [q to quit]? r
Something else broke: invalid literal for int() with base 10: 'r'
Position [q to quit]? q
```